Workbook

Sheet Overview
A1: DATA CLEANING AND EDA
A3: OVERVIEW
A4: This workbook contains a messy customer purchase dataset with:
A5: • Missing values (15% across multiple columns)
A6: • Duplicate rows (10 duplicates)
A7: • Inconsistent data formats (dates, gender, city, product categories)
A8: • Outliers in purchase amounts
A9: Total Records: 210 rows | Total Columns: 11
A11: TASK 1: DATA CLEANING AND PREPROCESSING
A12: 1."Raw_Data" sheet containing data and used to examine the dataset
A13: 2.Using Excel formulas to count blanks: =COUNTBLANK(range)
A14: Options: Delete rows with CTRL+- or fill with median/mode (only if data is not needed)
... A43: • Clear understanding of data distributions and relationships

Sheet Data_Dictionary
A1: DATA DICTIONARY
A2: Column Name | B2: Data Type | C2: Description | D2: Issues to Fix
A3: CustomerID | B3: Integer | C3: Unique customer identifier | D3: None
A4: Name | B4: Text | C4: Customer name | D4: None
A5: Age | B5: Integer | C5: Customer age (18-75 years) | D5: ~15% missing values
A6: Gender | B6: Category | C6: Customer gender | D6: Inconsistent values: Male/Female/M/F/male/MALE + missing
A7: City | B7: Category | C7: Customer city | D7: Inconsistent capitalization
A8: PurchaseDate | B8: Date | C8: Date of purchase | D8: Multiple date formats (YYYY-MM-DD, MM/DD/YYYY, etc.)
A9: ProductCategory | B9: Category | C9: Product category purchased | D9: Inconsistent capitalization
A10: PurchaseAmount | B10: Float | C10: Purchase amount in dollars | D10: ~15% missing + outliers present
A11: Quantity | B11: Integer | C11: Quantity purchased (1-10) | D11: None
A12: CustomerSatisfaction | B12: Integer | C12: Rating 1-5 (1=poor, 5=excellent) | D12: ~15% missing values
A13: DeliveryTime | B13: Integer | C13: Delivery time in days (1-15) | D13: ~14% missing values

Sheet Cleaned_data
A1: CustomerID | B1: Name | C1: Age | D1: Gender | E1: City | F1: PurchaseDate | G1: ProductCategory | H1: PurchaseAmount | I1: Quantity | J1: Unit Price | K1: CustomerSatisfaction | L1: DeliveryTime
A2: 1 | B2: Customer_1 | C2: 56 | D2: Male | E2: Chicago | F2: 45254 | G2: Electronics | H2: 86.96 | I2: 5 | J2: =H2/I2 -> 17.392 | K2: 0 | L2: 8
A3: 2 | B3: Customer_2 | C3: 69 | D3: Male | E3: New York | F3: 44939 | G3: Books | H3: 974.65 | I3: 4 | J3: =H3/I3 -> 243.6625 | K3: 4 | L3: 2
A4: 3 | B4: Customer_3 | C4: 46 | D4: Male | E4: Chicago | F4: 45082 | G4: Clothing | H4: 986.35 | I4: 3 | J4: =H4/I4 -> 328.78333 | K4: 1 | L4: 11
A5: 4 | B5: Customer_4 | C5: 32 | D5: Female | E5: Los Angeles | F5: 44998 | G5: Clothing | H5: 701.18 | I5: 1 | J5: =H5/I5 -> 701.18 | K5: 5 | L5: 7
A6: 5 | B6: Customer_5 | C6: 43.5 | D6: Female | E6: New York | F6: 45273 | G6: Electronics | H6: 540.74 | I6: 6 | J6: =H6/I6 -> 90.123333 | K6: 3 | L6: 13
A7: 6 | B7: Customer_6 | C7: 25 | D7: Male | E7: Los Angeles | F7: 45229 | G7: Food | H7: 654.16747 | I7: 2 | J7: =H7/I7 -> 327.08374 | K7: 2 | L7: 7.9588235
A8: 7 | B8: Customer_7 | C8: 38 | D8: Male | E8: Chicago | F8: 44943 | G8: Clothing | H8: 654.16747 | I8: 8 | J8: =H8/I8 -> 81.770934 | K8: 2 | L8: 14
A9: 8 | B9: Customer_8 | C9: 56 | D9: Male | E9: New York | F9: 02/17/2023 | G9: Food | H9: 687.88 | I9: 5 | J9: =H9/I9 -> 137.576 | K9: 3 | L9: 4
A10: 9 | B10: Customer_9 | C10: 36 | D10: Male | E10: Los Angeles | F10: 45046 | G10: Electronics | H10: 170.99 | I10: 7 | J10: =H10/I10 -> 24.427143 | K10: 2 | L10: 7
A11: 10 | B11: Customer_10 | C11: 43.5 | D11: Male | E11: Chicago | F11: 10/15/2023 | G11: Clothing | H11: 654.16747 | I11: 2 | J11: =H11/I11 -> 327.08374 | K11: 4 | L11: 3
A12: 11 | B12: Customer_11 | C12: 28 | D12: Male | E12: New York | F12: 45259 | G12: Electronics | H12: 824.31 | I12: 8 | J12: =H12/I12 -> 103.03875 | K12: 1 | L12: 2
A13: 12 | B13: Customer_12 | C13: 28 | D13: Male | E13: Los Angeles | F13: 45039 | G13: Clothing | H13: 950.3 | I13: 2 | J13: =H13/I13 -> 475.15 | K13: 4 | L13: 11
A14: 13 | B14: Customer_13 | C14: 41 | D14: Not specified | E14: Chicago | F14: 45228 | G14: Clothing | H14: 728.46 | I14: 4 | J14: =H14/I14 -> 182.115 | K14: 2 | L14: 10
A15: 14 | B15: Customer_14 | C15: 70 | D15: Female | E15: New York | F15: 45017 | G15: Clothing | H15: 617.28 | I15: 1 | J15: =H15/I15 -> 617.28 | K15: 5 | L15: 7
A16: 15 | B16: Customer_15 | C16: 53 | D16: Male | E16: Chicago | F16: 45284 | G16: Clothing | H16: 424.06 | I16: 5 | J16: =H16/I16 -> 84.812 | K16: 1 | L16: 1
A17: 16 | B17: Customer_16 | C17: 57 | D17: Male | E17: Los Angeles | F17: 45101 | G17: Clothing | H17: 933.4 | I17: 9 | J17: =H17/I17 -> 103.71111 | K17: 1 | L17: 7.9588235
A18: 17 | B18: Customer_17 | C18: 41 | D18: Male | E18: Chicago | F18: 03/21/2023 | G18: Food | H18: 654.16747 | I18: 1 | J18: =H18/I18 -> 654.16747 | K18: 3 | L18: 8
A19: 18 | B19: Customer_18 | C19: 20 | D19: Male | E19: Chicago | F19: 45099 | G19: Electronics | H19: 54.77 | I19: 9 | J19: =H19/I19 -> 6.0855556 | K19: 3 | L19: 3
A20: 19 | B20: Customer_19 | C20: 39 | D20: Not specified | E20: Los Angeles | F20: 44974 | G20: Books | H20: 36.1 | I20: 8 | J20: =H20/I20 -> 4.5125 | K20: 5 | L20: 12
A21: 20 | B21: Customer_20 | C21: 70 | D21: Male | E21: Los Angeles | F21: 44976 | G21: Clothing | H21: 382.7 | I21: 6 | J21: =H21/I21 -> 63.783333 | K21: 0 | L21: 12
A22: 21 | B22: Customer_21 | C22: 19 | D22: Male | E22: Los Angeles | F22: 45103 | G22: Electronics | H22: 812.45 | I22: 7 | J22: =H22/I22 -> 116.06429 | K22: 5 | L22: 13
A23: 22 | B23: Customer_22 | C23: 41 | D23: Male | E23: New York | F23: 44949 | G23: Clothing | H23: 987.4 | I23: 3 | J23: =H23/I23 -> 329.13333 | K23: 3 | L23: 7.9588235
A24: 23 | B24: Customer_23 | C24: 61 | D24: Male | E24: New York | F24: 45201 | G24: Electronics | H24: 158.91 | I24: 1 | J24: =H24/I24 -> 158.91 | K24: 3 | L24: 7.9588235
A25: 24 | B25: Customer_24 | C25: 47 | D25: Male | E25: New York | F25: 45120 | G25: Food | H25: 654.16747 | I25: 5 | J25: =H25/I25 -> 130.83349 | K25: 1 | L25: 5
A26: 25 | B26: Customer_25 | C26: 55 | D26: Female | E26: Chicago | F26: 45209 | G26: Electronics | H26: 387.08 | I26: 2 | J26: =H26/I26 -> 193.54 | K26: 0 | L26: 11
A27: 26 | B27: Customer_26 | C27: 19 | D27: Female | E27: New York | F27: 45248 | G27: Books | H27: 970.22 | I27: 5 | J27: =H27/I27 -> 194.044 | K27: 2 | L27: 8
A28: 27 | B28: Customer_27 | C28: 38 | D28: Not specified | E28: Chicago | F28: 10/23/2023 | G28: Electronics | H28: 843.7 | I28: 8 | J28: =H28/I28 -> 105.4625 | K28: 3 | L28: 7.9588235
A29: 28 | B29: Customer_28 | C29: 50 | D29: Male | E29: Phoenix | F29: 45287 | G29: Electronics | H29: 839.95 | I29: 9 | J29: =H29/I29 -> 93.327778 | K29: 0 | L29: 7
A30: 29 | B30: Customer_29 | C30: 29 | D30: Not specified | E30: Los Angeles | F30: 01/24/2023 | G30: Electronics | H30: 474.01 | I30: 2 | J30: =H30/I30 -> 237.005 | K30: 0 | L30: 7
A31: 30 | B31: Customer_30 | C31: 39 | D31: Not specified | E31: Chicago | F31: 45075 | G31: Electronics | H31: 420.67 | I31: 3 | J31: =H31/I31 -> 140.22333 | K31: 4 | L31: 12
A32: 31 | B32: Customer_31 | C32: 61 | D32: Male | E32: Los Angeles | F32: 45046 | G32: Books | H32: 280.67 | I32: 3 | J32: =H32/I32 -> 93.556667 | K32: 5 | L32: 7
A33: 32 | B33: Customer_32 | C33: 42 | D33: Male | E33: Chicago | F33: 45121 | G33: Clothing | H33: 654.16747 | I33: 1 | J33: =H33/I33 -> 654.16747 | K33: 5 | L33: 8
A34: 33 | B34: Customer_33 | C34: 66 | D34: Male | E34: Los Angeles | F34: 45159 | G34: Electronics | H34: 866.08 | I34: 8 | J34: =H34/I34 -> 108.26 | K34: 2 | L34: 7.9588235
A35: 34 | B35: Customer_34 | C35: 44 | D35: Female | E35: New York | F35: 45010 | G35: Electronics | H35: 814.77 | I35: 6 | J35: =H35/I35 -> 135.795 | K35: 0 | L35: 4
A36: 35 | B36: Customer_35 | C36: 59 | D36: Female | E36: Phoenix | F36: 44933 | G36: Food | H36: 999.72 | I36: 8 | J36: =H36/I36 -> 124.965 | K36: 1 | L36: 7.9588235
A37: 36 | B37: Customer_36 | C37: 45 | D37: Female | E37: Houston | F37: 45270 | G37: Electronics | H37: 996.67 | I37: 9 | J37: =H37/I37 -> 110.74111 | K37: 5 | L37: 6
A38: 37 | B38: Customer_37 | C38: 33 | D38: Male | E38: Los Angeles | F38: 45286 | G38: Food | H38: 559.88 | I38: 5 | J38: =H38/I38 -> 111.976 | K38: 3 | L38: 7.9588235
A39: 38 | B39: Customer_38 | C39: 32 | D39: Female | E39: Chicago | F39: 45149 | G39: Books | H39: 771.3 | I39: 3 | J39: =H39/I39 -> 257.1 | K39: 5 | L39: 13
A40: 39 | B40: Customer_39 | C40: 64 | D40: Male | E40: New York | F40: 44936 | G40: Clothing | H40: 945.32 | I40: 5 | J40: =H40/I40 -> 189.064 | K40: 0 | L40: 7.9588235
...

Sheet Analysis
A1: SUMMARY STATISTICS
A3: Stastistic | B3: Age | C3: Purchase amount | D3: Quantity | E3: Delivery time
A4: Mean (Average) | B4: =AVERAGE(Cleaned_data!C2:C201) -> 44.42 | C4: =AVERAGE(Cleaned_data!H2:H201) -> 654.16747 | D4: =AVERAGE(Cleaned_data!I2:I201) -> 4.955 | E4: =AVERAGE(Cleaned_data!L2:L201) -> 7.9588235
A5: Std Dev | B5: =_xlfn.STDEV.S(Cleaned_data!C2:C201) -> 14.960118 | C5: =_xlfn.STDEV.S(Cleaned_data!H2:H201) -> 1075.4841 | D5: =_xlfn.STDEV.S(Cleaned_data!I2:I201) -> 2.6205556 | E5: =_xlfn.STDEV.S(Cleaned_data!L2:L201) -> 3.7755573
A6: Min | B6: =MIN(Cleaned_data!C2:C201) -> 18 | C6: =MIN(Cleaned_data!H2:H201) -> 24.4 | D6: =MIN(Cleaned_data!I2:I201) -> 1 | E6: =MIN(Cleaned_data!L2:L201) -> 1
A7: Max | B7: =MAX(Cleaned_data!C2:C201) -> 74 | C7: =MAX(Cleaned_data!H2:H201) -> 9451.29 | D7: =MAX(Cleaned_data!I2:I201) -> 9 | E7: =MAX(Cleaned_data!L2:L201) -> 14
A9: FREQUENCY DISTRIBUTION
A11: Customer_ID | B11: Product Category
A12: Gender | B12: Books | C12: Clothing | D12: Electronics | E12: Food | F12: Grand Total
A13: Female | B13: 5 | C13: 12 | D13: 20 | E13: 10 | F13: 47
A14: Male | B14: 24 | C14: 37 | D14: 47 | E14: 15 | F14: 123
A15: Not specified | B15: 9 | C15: 8 | D15: 10 | E15: 3 | F15: 30
A16: Grand Total | B16: 38 | C16: 57 | D16: 77 | E16: 28 | F16: 200

Sheet Key_Visuals
M18: Category | N18: Average Amount
M19: Electronics | N19: =AVERAGEIF(Cleaned_data!G:G,"Electronics",Cleaned_data!H:H) -> 722.29321
M20: Books | N20: =AVERAGEIF(Cleaned_data!G:G,"Books",Cleaned_data!H:H) -> 658.26131
M21: Clothing | N21: =AVERAGEIF(Cleaned_data!G:G,"Clothing",Cleaned_data!H:H) -> 624.03197
M22: Food | N22: =AVERAGEIF(Cleaned_data!G:G,"Food",Cleaned_data!H:H) -> 522.61303
